<?xml version="1.0" ?>
<!-- =================================================================================== -->
<!-- |    This document was autogenerated by xacro from forklift.xacro                 | -->
<!-- |    EDITING THIS FILE BY HAND IS NOT RECOMMENDED                                 | -->
<!-- =================================================================================== -->
<!-- Forklift -->
<robot name="forklift" xmlns:xacro="http://www.ros.org/wiki/xacro">
  <!-- ros_control plugin -->
  <gazebo>
    <plugin filename="libgazebo_ros_control.so" name="gazebo_ros_control">
      <robotNamespace>forklift</robotNamespace>
      <robotSimType>gazebo_ros_control/DefaultRobotHWSim</robotSimType>
      <rosDebugLevel>Debug</rosDebugLevel>
    </plugin>
  </gazebo>
  <!-- Body -->
  <gazebo reference="forklift_body">
  </gazebo>
  <!-- Lift1 -->
  <gazebo reference="forklift_lift1">
  </gazebo>
  <!-- Lift2 -->
  <gazebo reference="forklift_lift2">
  </gazebo>
  <!-- FL Wheel -->
  <gazebo reference="forklift_wheelFL">
    <mu1 value="100000.0"/>
    <mu2 value="100000.0"/>
    <fdir1>0 1 0</fdir1>
    <minDepth>0.01</minDepth>
    <maxVel>1.0</maxVel>
    <slip1 value="0"/>
    <slip2 value="0"/>
  </gazebo>
  <!-- FR Wheel -->
  <gazebo reference="forklift_wheelFR">
    <mu1 value="100000.0"/>
    <mu2 value="100000.0"/>
    <fdir1>0 1 0</fdir1>
    <minDepth>0.01</minDepth>
    <maxVel>1.0</maxVel>
    <slip1 value="0"/>
    <slip2 value="0"/>
  </gazebo>
  <!-- BL Wheel -->
  <!--
  <gazebo reference="forklift_wheelBL">
    <mu1 value="0.0"/>
    <mu2 value="0.0"/>
    <slip1>1.0</slip1>
    <slip2>1.0</slip2>
    <minDepth>0.01</minDepth>
  </gazebo>
  -->
  <!-- BR Wheel -->
  <!--
  <gazebo reference="forklift_wheelBR">
    <mu1 value="0.0"/>
    <mu2 value="0.0"/>
    <slip1>1.0</slip1>
    <slip2>1.0</slip2>
    <minDepth>0.01</minDepth>
  </gazebo> 
  -->
  <!-- Caster Wheel -->
  <gazebo reference="caster_wheel">
    <mu1 value="0.0"/>
    <mu2 value="0.0"/>
    <slip1>1.0</slip1>
    <slip2>1.0</slip2>
  </gazebo>
  <!-- Forklift -->
  <link name="forklift_body">
    <collision>
      <origin rpy="0 0 0" xyz="0 0 1.15"/>
      <geometry>
        <box size="1.2 2.65 1.9"/>
      </geometry>
    </collision>
    <visual>
      <origin rpy="0 0 0" xyz="-0.00203 -0.06282 1.08726"/>
      <geometry>
        <mesh filename="package://forklift_description/meshes/forklift_body.dae"/>
      </geometry>
    </visual>
    <inertial>
      <origin rpy="0 0 0" xyz="0 0 1"/>
      <mass value="50"/>
      <inertia ixx="33.3333333333" ixy="0.0" ixz="0.0" iyy="23.7083333333" iyz="0.0" izz="23.7083333333"/>
    </inertial>
  </link>
  <joint name="lift1_joint" type="prismatic">
    <parent link="forklift_body"/>
    <child link="forklift_lift1"/>
    <axis xyz="0 0 1"/>
    <limit effort="1000" lower="0" upper="3" velocity="0.5"/>
  </joint>
  <link name="forklift_lift1">
    <collision>
      <origin rpy="0 0 0" xyz="0 -1.44 0.695"/>
      <geometry>
        <box size="1.2 0.1 1.25"/>
      </geometry>
    </collision>
    <collision>
      <origin rpy="0 0 0" xyz="0.32 -2.1 0.06"/>
      <geometry>
        <box size="0.13 1.2 0.03"/>
      </geometry>
    </collision>
    <collision>
      <origin rpy="0 0 0" xyz="-0.32 -2.1 0.06"/>
      <geometry>
        <box size="0.13 1.2 0.03"/>
      </geometry>
    </collision>
    <visual>
      <origin rpy="0 0 0" xyz="0 0 0"/>
      <geometry>
        <mesh filename="package://forklift_description/meshes/forklift_lift1.dae"/>
      </geometry>
    </visual>
    <inertial>
      <origin rpy="0 0 0" xyz="0 -1.4 0.6"/>
      <mass value="10"/>
      <inertia ixx="0.908333333333" ixy="0.0" ixz="0.0" iyy="1.66666666667" iyz="0.0" izz="0.908333333333"/>
    </inertial>
  </link>
  <joint name="lift2_joint" type="fixed">
    <parent link="forklift_body"/>
    <child link="forklift_lift2"/>
    <axis xyz="0 0 1"/>
    <limit effort="1" lower="0" upper="3" velocity="1"/>
    <mimic joint="lift1_joint" multiplier="0.5"/>
  </joint>
  <link name="forklift_lift2">
    <collision>
      <origin rpy="0 0 0" xyz="0 -1.18 1.05"/>
      <geometry>
        <box size="0.7 0.3 2"/>
      </geometry>
    </collision>
    <visual>
      <origin rpy="0 0 0" xyz="0 0 0"/>
      <geometry>
        <mesh filename="package://forklift_description/meshes/forklift_lift2.dae"/>
      </geometry>
    </visual>
    <inertial>
      <origin rpy="0 0 0" xyz="0 -1.2 0.695"/>
      <mass value="10"/>
      <inertia ixx="3.46666666667" ixy="0.0" ixz="0.0" iyy="3.74166666667" iyz="0.0" izz="0.541666666667"/>
    </inertial>
  </link>
  <transmission name="lift_transmission">
    <type>transmission_interface/SimpleTransmission</type>
    <joint name="lift1_joint">
      <hardwareInterface>VelocityJointInterface</hardwareInterface>
    </joint>
    <actuator name="lift_motor">
      <hardwareInterface>VelocityJointInterface</hardwareInterface>
      <mechanicalReduction>1</mechanicalReduction>
    </actuator>
  </transmission>
  <!-- FR Wheel -->
  <joint name="wheelFR_joint" type="continuous">
    <parent link="forklift_body"/>
    <child link="forklift_wheelFR"/>
    <axis xyz="1 0 0"/>
    <origin xyz="-0.49389 -0.90059 0.34047"/>
  </joint>
  <link name="forklift_wheelFR">
    <collision>
      <origin rpy="0 1.57079632679 0" xyz="0 0 0"/>
      <geometry>
        <cylinder length="0.01" radius="0.33"/>
      </geometry>
    </collision>
    <visual>
      <origin rpy="0 0 3.14159265359" xyz="0 0 0"/>
      <geometry>
        <mesh filename="package://forklift_description/meshes/forklift_wheel_front.dae"/>
      </geometry>
    </visual>
    <inertial>
      <origin rpy="0 1.57079632679 0" xyz="0 0 0"/>
      <mass value="10"/>
      <inertia ixx="0.272333333333" ixy="0" ixz="0" iyy="0.272333333333" iyz="0" izz="0.5445"/>
    </inertial>
  </link>
  <!-- FL Wheel -->
  <joint name="wheelFL_joint" type="continuous">
    <parent link="forklift_body"/>
    <child link="forklift_wheelFL"/>
    <axis xyz="1 0 0"/>
    <origin xyz="0.49389 -0.90059 0.34047"/>
  </joint>
  <link name="forklift_wheelFL">
    <collision>
      <origin rpy="0 1.57079632679 0" xyz="0 0 0"/>
      <geometry>
        <cylinder length="0.01" radius="0.33"/>
      </geometry>
    </collision>
    <visual>
      <origin rpy="0 0 0" xyz="0 0 0"/>
      <geometry>
        <mesh filename="package://forklift_description/meshes/forklift_wheel_front.dae"/>
      </geometry>
    </visual>
    <inertial>
      <origin rpy="0 1.57079632679 0" xyz="0 0 0"/>
      <mass value="10"/>
      <inertia ixx="0.272333333333" ixy="0" ixz="0" iyy="0.272333333333" iyz="0" izz="0.5445"/>
    </inertial>
  </link>
  <transmission name="front_right_wheel_transmission">
    <type>hardware_interface</type>
    <joint name="wheelFR_joint">
      <hardwareInterface>VelocityJointInterface</hardwareInterface>
    </joint>
    <actuator name="front_wheel_motor">
      <hardwareInterface>VelocityJointInterface</hardwareInterface>
      <mechanicalReduction>1</mechanicalReduction>
    </actuator>
  </transmission>
  <transmission name="front_left_wheel_transmission">
    <type>hardware_interface</type>
    <joint name="wheelFL_joint">
      <hardwareInterface>VelocityJointInterface</hardwareInterface>
    </joint>
    <actuator name="front_wheel_motor">
      <hardwareInterface>VelocityJointInterface</hardwareInterface>
      <mechanicalReduction>1</mechanicalReduction>
    </actuator>
  </transmission>
  <!-- Import back wheels -->
  <!--<xacro:include filename="$(find forklift_description)/urdf/forklift_back_wheels.xacro" />-->
  <!-- caster Wheel -->
  <joint name="caster_wheel_joint" type="continuous">
    <parent link="forklift_body"/>
    <child link="caster_wheel"/>
    <origin xyz="0.0 0.76717 0.27997"/>
    <axis xyz="0 1 0"/>
  </joint>
  <link name="caster_wheel">
    <collision>
      <origin rpy="0 1.57079632679 0" xyz="0 0 0"/>
      <geometry>
        <sphere radius="0.27"/>
      </geometry>
    </collision>
    <visual>
      <origin rpy="0 1.57079632679 0" xyz="0 0 0"/>
      <geometry>
        <sphere radius="0.27"/>
      </geometry>
    </visual>
    <inertial>
      <origin rpy="0 1.57079632679 0" xyz="0 0 0"/>
      <mass value="0"/>
      <inertia ixx="0" ixy="0" ixz="0" iyy="0" iyz="0" izz="0"/>
    </inertial>
  </link>
</robot>
